Workbook
Name LIQUIDACION: Hoja1!$B$14

Sheet Hoja1
A1: EMPRESA MINERA NERCAVE S.R.L.
A3: DATOS | D3: LEYES
D4: Zn | E4: 5 | G4: 0 | I4: LEY | J4: $U$ ZN | K4: SUS TMH Zn | L4: PRECIO PLATA | N4: SUS TMH Ag.
A5: Fecha | B5: =+TODAY() -> 46253 | D5: Ag | E5: 6.5 | G5: 2 | I5: % Zn | J5: USD/Punto | L5: (DM) | M5: USD/DM
A6: Nombre | B6: NELSON CAVERO | D6: Pb | E6: 13 | G6: 0 | I6: 0 | J6: 5.5 | K6: =I6*J6 -> 0 | L6: 0 | M6: 0 | N6: =L6*M6 -> 0
A7: Cooperativa | B7: KORI MAYU | D7: PESO | E7: 450 | I7: 6 | J7: 6 | K7: =I7*J7 -> 36 | L7: 1 | M7: 2 | N7: =L7*M7 -> 2
A8: Municipio | B8: POTOSI | D8: H2O | E8: 0.05 | I8: =I7+1 -> 7 | J8: 9 | K8: =I8*J8 -> 63 | L8: =L7+1 -> 2 | M8: 8 | N8: =L8*M8 -> 16
A9: Procendencia /Mina: | B9: MONJA 2 | D9: =E4-G4 -> 5 | E9: =LOOKUP(D9,I6:I51,J6:J51) -> 5.5 | F9: =E9*D9 -> 27.5 | I9: =I8+1 -> 8 | J9: 7.5 | K9: =I9*J9 -> 60 | L9: =L8+1 -> 3 | M9: 5 | N9: =L9*M9 -> 15
A10: LOTE | B10: 334 | D10: =E5-G5 -> 4.5 | E10: =LOOKUP(D10,L6:L14,M6:M14) -> 5.2 | F10: =E10*D10 -> 23.4 | I10: =I9+1 -> 9 | J10: 8.3 | K10: =I10*J10 -> 74.7 | L10: =L9+1 -> 4 | M10: 5.2 | N10: =L10*M10 -> 20.8
D11: =E6-G6 -> 13 | E11: =LOOKUP(D11,L18:L30,M18:M30) -> 8 | F11: =D11*E11 -> 104 | I11: =I10+1 -> 10 | J11: 9.3 | K11: =I11*J11 -> 93 | L11: =L10+1 -> 5 | M11: 5.5 | N11: =L11*M11 -> 27.5
F12: =F9+F10+F11 -> 154.9 | I12: =I11+1 -> 11 | J12: 10 | K12: =I12*J12 -> 110 | L12: =L11+1 -> 6 | M12: 6 | N12: =L12*M12 -> 36
B13: Liquidación | D13: TIPO DE CAMBIO | F13: 6.86 | I13: =I12+1 -> 12 | J13: 10.1 | K13: =I13*J13 -> 121.2 | L13: =L12+1 -> 7 | M13: 6.2 | N13: =L13*M13 -> 43.4
I14: =I13+1 -> 13 | J14: 10.3 | K14: =I14*J14 -> 133.9 | L14: =L13+1 -> 8 | M14: 6.5 | N14: =L14*M14 -> 52
I15: =I14+1 -> 14 | J15: 10.5 | K15: =I15*J15 -> 147
I16: =I15+1 -> 15 | J16: 10.65 | K16: =I16*J16 -> 159.75 | L16: PRECIO PLOMO | N16: SUS TMH Pb
I17: =I16+1 -> 16 | J17: 11.1 | K17: =I17*J17 -> 177.6 | L17: % Pb | M17: USD/Punto
I18: =I17+1 -> 17 | J18: 11.5 | K18: =I18*J18 -> 195.5 | L18: 0 | M18: 3.7 | N18: =L18*M18 -> 0
I19: =I18+1 -> 18 | J19: 11.6 | K19: =I19*J19 -> 208.8 | L19: 6 | M19: 5 | N19: =L19*M19 -> 30
I20: =I19+1 -> 19 | J20: 11.9 | K20: =I20*J20 -> 226.1 | L20: 8 | M20: 6 | N20: =L20*M20 -> 48
I21: =I20+1 -> 20 | J21: 12 | K21: =I21*J21 -> 240 | L21: 10 | M21: 7 | N21: =L21*M21 -> 70
I22: =I21+1 -> 21 | J22: 12.3 | K22: =I22*J22 -> 258.3 | L22: 12 | M22: 8 | N22: =L22*M22 -> 96
I23: =I22+1 -> 22 | J23: 12.5 | K23: =I23*J23 -> 275 | L23: 14 | M23: 9 | N23: =L23*M23 -> 126
I24: =I23+1 -> 23 | J24: 12.6 | K24: =I24*J24 -> 289.8 | L24: 16 | M24: 10 | N24: =L24*M24 -> 160
I25: =I24+1 -> 24 | J25: 12.7 | K25: =I25*J25 -> 304.8 | L25: 18 | M25: 11.5 | N25: =L25*M25 -> 207
I26: =I25+1 -> 25 | J26: 12.8 | K26: =I26*J26 -> 320 | L26: 20 | M26: 4.6 | N26: =L26*M26 -> 92
I27: =I26+1 -> 26 | J27: 12.9 | K27: =I27*J27 -> 335.4 | L27: 22 | M27: 4.6 | N27: =L27*M27 -> 101.2
I28: =I27+1 -> 27 | J28: 13 | K28: =I28*J28 -> 351 | L28: 24 | M28: 4.8 | N28: =L28*M28 -> 115.2
I29: =I28+1 -> 28 | J29: 13.1 | K29: =I29*J29 -> 366.8 | L29: 26 | M29: 5 | N29: =L29*M29 -> 130
I30: =I29+1 -> 29 | J30: 13.2 | K30: =I30*J30 -> 382.8 | L30: 28 | M30: 5.2 | N30: =L30*M30 -> 145.6
I31: =I30+1 -> 30 | J31: 14.5 | K31: =I31*J31 -> 435
I32: =I31+1 -> 31 | J32: 14.6 | K32: =I32*J32 -> 452.6
I33: =I32+1 -> 32 | J33: =J32+0.05 -> 14.65 | K33: =I33*J33 -> 468.8
I34: =I33+1 -> 33 | J34: =J33+0.05 -> 14.7 | K34: =I34*J34 -> 485.1
I35: =I34+1 -> 34 | J35: =J34+0.05 -> 14.75 | K35: =I35*J35 -> 501.5
I36: =I35+1 -> 35 | J36: =J35+0.05 -> 14.8 | K36: =I36*J36 -> 518
I37: =I36+1 -> 36 | J37: =J36+0.044 -> 14.844 | K37: =I37*J37 -> 534.384
I38: =I37+1 -> 37 | J38: =J37+0.014 -> 14.858 | K38: =I38*J38 -> 549.746
I39: =I38+1 -> 38 | J39: =J38+0.013 -> 14.871 | K39: =I39*J39 -> 565.098
I40: =I39+1 -> 39 | J40: =J39+0.001 -> 14.872 | K40: =I40*J40 -> 580.008
I41: =I40+1 -> 40 | J41: 5.373 | K41: =I41*J41 -> 214.92
...

Sheet LIQ. 
F4: N° | G4: =LARGE(#REF!,1)+1 -> #REF!
E5: Potosí - Bolivia
B7: LIQUIDACIÓN DE MINERAL
B8: Fecha: | C8: =Hoja1!B5 -> 46253 | E8: Lote: | F8: =IF(Hoja1!B10="","",Hoja1!B10) -> 334 | G8: 1RA QUINCENA DE SEPTIEMBRE
B9: Nombre: | C9: =IF(Hoja1!B6="","",Hoja1!B6) -> NELSON CAVERO | G9: Cotización Oficial Zn: | H9: 1.11
B10: Cooperativa: | C10: =IF(Hoja1!B7="","",Hoja1!B7) -> KORI MAYU | G10: Cotización Oficial Ag: | H10: 27.08
B11: Municipio: | C11: =IF(Hoja1!B8="","",Hoja1!B8) -> POTOSI | G11: Cotización Oficial Pb: | H11: 0.89
B12: Procendencia/Mina: | D12: =IF(Hoja1!B9="","",Hoja1!B9) -> MONJA 2
B13: LEY ZN | C13: =Hoja1!E4 -> 5 | D13: Peso Hum: | E13: =Hoja1!E7 -> 450 | F13: VALOR TONELADA Bs.: | G13: =Hoja1!F12*Hoja1!F13/1000 -> 1.062614
B14: LEY AG | C14: =Hoja1!E5 -> 6.5 | D14: Peso Seco: | E14: =ROUNDDOWN(E13-(Hoja1!E8*E13),3) -> 427.5
B15: LEY Pb | C15: =Hoja1!E6 -> 13
B16: VALORACIÓN LOTE Bs.: | F16: =E14*G13*1000 -> 454267.48
B17: Regalía Zn;3% Ag;3,6% Pb;3% | D17: 0.068 | F17: =F16*D17 -> 30890.189
B18: C.N.S. 1,80 % | D18: 0.018 | F18: =D18*$F$16 -> 8176.8147 | O18: 200 | P18: =+O18/22 -> 9.0909091
B19: COMIBOL 1% | D19: 0.01 | F19: =D19*$F$16 -> 4542.6749
B20: FEDECOMIN 1% | D20: 0.01 | F20: =D20*$F$16 -> 4542.6749
B21: FENCOMIN 0,4% | D21: 0.004 | F21: =D21*$F$16 -> 1817.0699
B22: COOPERATIVA | D22: 0 | F22: =D22*$F$16 -> 0
B25: TOTAL DESCUENTOS | F25: =F17+F18+F19+F20+F21+F22+F23 -> 49969.423
B26: TOTAL LIQUIDACIÓN: | F26: =F16-F25 -> 404298.06
B27: DEDUCCIONES: | D27: OTROS ANTICIPOS | F27: 11
D28: ANTICIPO | F28: 200
B29: LIQUIDO PAGABLE: | F29: =F26-F27-F28 -> 404087.06
B35: ADMINISTRADOR | E35: CLIENTE
B36: C.I.: | E36: C.I.:
B37: Entregue conforme | E37: Recibi conforme
